<?xml version="0.0" ?>
<robot name="triroller">
	<link name="base_link">
		<inertial>
			<origin rpy="0.00000 -0.00000 0.00000" xyz="0.00000 0.00000 0.00000"/>
			<mass value="5.02655"/>
			<inertia ixx="0.05094" ixy="0" ixz="0" iyy="0.05094" iyz="0" izz="0.10053"/>
		</inertial>
	</link>
	<link name="link0_2">
		<inertial>
			<origin rpy="0.00000 -0.00000 0.00000" xyz="0.00000 0.00000 0.00000"/>
			<mass value="0.00000"/>
			<inertia ixx="0.00000" ixy="0" ixz="0" iyy="0.00000" iyz="0" izz="0.00000"/>
		</inertial>
	</link>
	<link name="l1_front">
		<inertial>
			<origin rpy="0.00000 -0.00000 0.00000" xyz="0.00000 0.00000 0.00000"/>
			<mass value="0.01200"/>
			<inertia ixx="0.00000" ixy="0" ixz="0" iyy="0.00000" iyz="0" izz="0.00000"/>
		</inertial>
		<collision>
			<origin rpy="0.00000 -0.00000 0.00000" xyz="0.00000 0.00000 0.00000"/>
			<geometry>
				<box size="0.04000 0.03000 0.01000"/>
			</geometry>
		</collision>
		<visual>
			<origin rpy="0.00000 -0.00000 0.00000" xyz="0.00000 0.00000 0.00000"/>
			<geometry>
				<box size="0.04000 0.03000 0.01000"/>
			</geometry>
		</visual>
	</link>
	<link name="l11_front">
		<inertial>
			<origin rpy="0.00000 -0.00000 0.00000" xyz="0.00000 0.00000 0.00000"/>
			<mass value="0.03795"/>
			<inertia ixx="0.00005" ixy="0" ixz="0" iyy="0.00005" iyz="0" izz="0.00000"/>
		</inertial>
		<collision>
			<origin rpy="0.00000 -0.00000 0.00000" xyz="0.00000 0.00000 0.00000"/>
			<geometry>
				<box size="0.01000 0.03000 0.12650"/>
			</geometry>
		</collision>
		<visual>
			<origin rpy="0.00000 -0.00000 0.00000" xyz="0.00000 0.00000 0.00000"/>
			<geometry>
				<box size="0.01000 0.03000 0.12650"/>
			</geometry>
		</visual>
	</link>
	<link name="link0_5">
		<inertial>
			<origin rpy="0.00000 -0.00000 0.00000" xyz="0.00000 0.00000 0.00000"/>
			<mass value="0.00000"/>
			<inertia ixx="0.00000" ixy="0" ixz="0" iyy="0.00000" iyz="0" izz="0.00000"/>
		</inertial>
	</link>
	<link name="l2_front">
		<inertial>
			<origin rpy="0.00000 -0.00000 0.00000" xyz="0.00000 0.00000 0.00000"/>
			<mass value="0.00500"/>
			<inertia ixx="0.00000" ixy="0" ixz="0" iyy="0.00000" iyz="0" izz="0.00000"/>
		</inertial>
		<collision>
			<origin rpy="0.00000 -0.00000 0.00000" xyz="0.00000 0.00000 0.00000"/>
			<geometry>
				<box size="0.01000 0.01000 0.05000"/>
			</geometry>
		</collision>
		<visual>
			<origin rpy="0.00000 -0.00000 0.00000" xyz="0.00000 0.00000 0.00000"/>
			<geometry>
				<box size="0.01000 0.01000 0.05000"/>
			</geometry>
		</visual>
	</link>
	<link name="link0_7">
		<inertial>
			<origin rpy="0.00000 -0.00000 0.00000" xyz="0.00000 0.00000 0.00000"/>
			<mass value="0.00000"/>
			<inertia ixx="0.00000" ixy="0" ixz="0" iyy="0.00000" iyz="0" izz="0.00000"/>
		</inertial>
	</link>
	<link name="l3_front">
		<inertial>
			<origin rpy="0.00000 -0.00000 0.00000" xyz="0.00000 0.00000 0.00000"/>
			<mass value="0.04163"/>
			<inertia ixx="0.00001" ixy="0" ixz="0" iyy="0.00001" iyz="0" izz="0.00001"/>
		</inertial>
		<collision>
			<origin rpy="0.00000 -0.00000 0.00000" xyz="0.00000 0.00000 0.00000"/>
			<geometry>
				<sphere radius="0.02150"/>
			</geometry>
		</collision>
		<visual>
			<origin rpy="0.00000 -0.00000 0.00000" xyz="0.00000 0.00000 0.00000"/>
			<geometry>
				<sphere radius="0.02150"/>
			</geometry>
		</visual>
	</link>
	<link name="l31_front">
		<inertial>
			<origin rpy="0.00000 -0.00000 0.00000" xyz="0.00000 0.00000 0.00000"/>
			<mass value="0.00043"/>
			<inertia ixx="0.00000" ixy="0" ixz="0" iyy="0.00000" iyz="0" izz="0.00000"/>
		</inertial>
		<collision>
			<origin rpy="0.00000 -0.00000 0.00000" xyz="0.00000 0.00000 0.00000"/>
			<geometry>
				<box size="0.03600 0.00400 0.00300"/>
			</geometry>
		</collision>
		<visual>
			<origin rpy="0.00000 -0.00000 0.00000" xyz="0.00000 0.00000 0.00000"/>
			<geometry>
				<box size="0.03600 0.00400 0.00300"/>
			</geometry>
		</visual>
	</link>
	<link name="l32_front">
		<inertial>
			<origin rpy="0.00000 -0.00000 0.00000" xyz="0.00000 0.00000 0.00000"/>
			<mass value="0.00043"/>
			<inertia ixx="0.00000" ixy="0" ixz="0" iyy="0.00000" iyz="0" izz="0.00000"/>
		</inertial>
		<collision>
			<origin rpy="0.00000 -0.00000 0.00000" xyz="0.00000 0.00000 0.00000"/>
			<geometry>
				<box size="0.03600 0.00400 0.00300"/>
			</geometry>
		</collision>
		<visual>
			<origin rpy="0.00000 -0.00000 0.00000" xyz="0.00000 0.00000 0.00000"/>
			<geometry>
				<box size="0.03600 0.00400 0.00300"/>
			</geometry>
		</visual>
	</link>
	<link name="link0_11">
		<inertial>
			<origin rpy="0.00000 -0.00000 0.00000" xyz="0.00000 0.00000 0.00000"/>
			<mass value="0.00000"/>
			<inertia ixx="0.00000" ixy="0" ixz="0" iyy="0.00000" iyz="0" izz="0.00000"/>
		</inertial>
	</link>
	<link name="l1_left">
		<inertial>
			<origin rpy="0.00000 -0.00000 0.00000" xyz="0.00000 0.00000 0.00000"/>
			<mass value="0.01200"/>
			<inertia ixx="0.00000" ixy="0" ixz="0" iyy="0.00000" iyz="0" izz="0.00000"/>
		</inertial>
		<collision>
			<origin rpy="0.00000 -0.00000 0.00000" xyz="0.00000 0.00000 0.00000"/>
			<geometry>
				<box size="0.04000 0.03000 0.01000"/>
			</geometry>
		</collision>
		<visual>
			<origin rpy="0.00000 -0.00000 0.00000" xyz="0.00000 0.00000 0.00000"/>
			<geometry>
				<box size="0.04000 0.03000 0.01000"/>
			</geometry>
		</visual>
	</link>
	<link name="l11_left">
		<inertial>
			<origin rpy="0.00000 -0.00000 0.00000" xyz="0.00000 0.00000 0.00000"/>
			<mass value="0.03795"/>
			<inertia ixx="0.00005" ixy="0" ixz="0" iyy="0.00005" iyz="0" izz="0.00000"/>
		</inertial>
		<collision>
			<origin rpy="0.00000 -0.00000 0.00000" xyz="0.00000 0.00000 0.00000"/>
			<geometry>
				<box size="0.01000 0.03000 0.12650"/>
			</geometry>
		</collision>
		<visual>
			<origin rpy="0.00000 -0.00000 0.00000" xyz="0.00000 0.00000 0.00000"/>
			<geometry>
				<box size="0.01000 0.03000 0.12650"/>
			</geometry>
		</visual>
	</link>
	<link name="link0_14">
		<inertial>
			<origin rpy="0.00000 -0.00000 0.00000" xyz="0.00000 0.00000 0.00000"/>
			<mass value="0.00000"/>
			<inertia ixx="0.00000" ixy="0" ixz="0" iyy="0.00000" iyz="0" izz="0.00000"/>
		</inertial>
	</link>
	<link name="l2_left">
		<inertial>
			<origin rpy="0.00000 -0.00000 0.00000" xyz="0.00000 0.00000 0.00000"/>
			<mass value="0.00500"/>
			<inertia ixx="0.00000" ixy="0" ixz="0" iyy="0.00000" iyz="0" izz="0.00000"/>
		</inertial>
		<collision>
			<origin rpy="0.00000 -0.00000 0.00000" xyz="0.00000 0.00000 0.00000"/>
			<geometry>
				<box size="0.01000 0.01000 0.05000"/>
			</geometry>
		</collision>
		<visual>
			<origin rpy="0.00000 -0.00000 0.00000" xyz="0.00000 0.00000 0.00000"/>
			<geometry>
				<box size="0.01000 0.01000 0.05000"/>
			</geometry>
		</visual>
	</link>
	<link name="link0_16">
		<inertial>
			<origin rpy="0.00000 -0.00000 0.00000" xyz="0.00000 0.00000 0.00000"/>
			<mass value="0.00000"/>
			<inertia ixx="0.00000" ixy="0" ixz="0" iyy="0.00000" iyz="0" izz="0.00000"/>
		</inertial>
	</link>
	<link name="l3_left">
		<inertial>
			<origin rpy="0.00000 -0.00000 0.00000" xyz="0.00000 0.00000 0.00000"/>
			<mass value="0.04163"/>
			<inertia ixx="0.00001" ixy="0" ixz="0" iyy="0.00001" iyz="0" izz="0.00001"/>
		</inertial>
		<collision>
			<origin rpy="0.00000 -0.00000 0.00000" xyz="0.00000 0.00000 0.00000"/>
			<geometry>
				<sphere radius="0.02150"/>
			</geometry>
		</collision>
		<visual>
			<origin rpy="0.00000 -0.00000 0.00000" xyz="0.00000 0.00000 0.00000"/>
			<geometry>
				<sphere radius="0.02150"/>
			</geometry>
		</visual>
	</link>
	<link name="l31_left">
		<inertial>
			<origin rpy="0.00000 -0.00000 0.00000" xyz="0.00000 0.00000 0.00000"/>
			<mass value="0.00043"/>
			<inertia ixx="0.00000" ixy="0" ixz="0" iyy="0.00000" iyz="0" izz="0.00000"/>
		</inertial>
		<collision>
			<origin rpy="0.00000 -0.00000 0.00000" xyz="0.00000 0.00000 0.00000"/>
			<geometry>
				<box size="0.03600 0.00400 0.00300"/>
			</geometry>
		</collision>
		<visual>
			<origin rpy="0.00000 -0.00000 0.00000" xyz="0.00000 0.00000 0.00000"/>
			<geometry>
				<box size="0.03600 0.00400 0.00300"/>
			</geometry>
		</visual>
	</link>
	<link name="l32_left">
		<inertial>
			<origin rpy="0.00000 -0.00000 0.00000" xyz="0.00000 0.00000 0.00000"/>
			<mass value="0.00043"/>
			<inertia ixx="0.00000" ixy="0" ixz="0" iyy="0.00000" iyz="0" izz="0.00000"/>
		</inertial>
		<collision>
			<origin rpy="0.00000 -0.00000 0.00000" xyz="0.00000 0.00000 0.00000"/>
			<geometry>
				<box size="0.03600 0.00400 0.00300"/>
			</geometry>
		</collision>
		<visual>
			<origin rpy="0.00000 -0.00000 0.00000" xyz="0.00000 0.00000 0.00000"/>
			<geometry>
				<box size="0.03600 0.00400 0.00300"/>
			</geometry>
		</visual>
	</link>
	<link name="link0_20">
		<inertial>
			<origin rpy="0.00000 -0.00000 0.00000" xyz="0.00000 0.00000 0.00000"/>
			<mass value="0.00000"/>
			<inertia ixx="0.00000" ixy="0" ixz="0" iyy="0.00000" iyz="0" izz="0.00000"/>
		</inertial>
	</link>
	<link name="l1_right">
		<inertial>
			<origin rpy="0.00000 -0.00000 0.00000" xyz="0.00000 0.00000 0.00000"/>
			<mass value="0.01200"/>
			<inertia ixx="0.00000" ixy="0" ixz="0" iyy="0.00000" iyz="0" izz="0.00000"/>
		</inertial>
		<collision>
			<origin rpy="0.00000 -0.00000 0.00000" xyz="0.00000 0.00000 0.00000"/>
			<geometry>
				<box size="0.04000 0.03000 0.01000"/>
			</geometry>
		</collision>
		<visual>
			<origin rpy="0.00000 -0.00000 0.00000" xyz="0.00000 0.00000 0.00000"/>
			<geometry>
				<box size="0.04000 0.03000 0.01000"/>
			</geometry>
		</visual>
	</link>
	<link name="l11_right">
		<inertial>
			<origin rpy="0.00000 -0.00000 0.00000" xyz="0.00000 0.00000 0.00000"/>
			<mass value="0.03795"/>
			<inertia ixx="0.00005" ixy="0" ixz="0" iyy="0.00005" iyz="0" izz="0.00000"/>
		</inertial>
		<collision>
			<origin rpy="0.00000 -0.00000 0.00000" xyz="0.00000 0.00000 0.00000"/>
			<geometry>
				<box size="0.01000 0.03000 0.12650"/>
			</geometry>
		</collision>
		<visual>
			<origin rpy="0.00000 -0.00000 0.00000" xyz="0.00000 0.00000 0.00000"/>
			<geometry>
				<box size="0.01000 0.03000 0.12650"/>
			</geometry>
		</visual>
	</link>
	<link name="link0_23">
		<inertial>
			<origin rpy="0.00000 -0.00000 0.00000" xyz="0.00000 0.00000 0.00000"/>
			<mass value="0.00000"/>
			<inertia ixx="0.00000" ixy="0" ixz="0" iyy="0.00000" iyz="0" izz="0.00000"/>
		</inertial>
	</link>
	<link name="l2_right">
		<inertial>
			<origin rpy="0.00000 -0.00000 0.00000" xyz="0.00000 0.00000 0.00000"/>
			<mass value="0.00500"/>
			<inertia ixx="0.00000" ixy="0" ixz="0" iyy="0.00000" iyz="0" izz="0.00000"/>
		</inertial>
		<collision>
			<origin rpy="0.00000 -0.00000 0.00000" xyz="0.00000 0.00000 0.00000"/>
			<geometry>
				<box size="0.01000 0.01000 0.05000"/>
			</geometry>
		</collision>
		<visual>
			<origin rpy="0.00000 -0.00000 0.00000" xyz="0.00000 0.00000 0.00000"/>
			<geometry>
				<box size="0.01000 0.01000 0.05000"/>
			</geometry>
		</visual>
	</link>
	<link name="link0_25">
		<inertial>
			<origin rpy="0.00000 -0.00000 0.00000" xyz="0.00000 0.00000 0.00000"/>
			<mass value="0.00000"/>
			<inertia ixx="0.00000" ixy="0" ixz="0" iyy="0.00000" iyz="0" izz="0.00000"/>
		</inertial>
	</link>
	<link name="l3_right">
		<inertial>
			<origin rpy="0.00000 -0.00000 0.00000" xyz="0.00000 0.00000 0.00000"/>
			<mass value="0.04163"/>
			<inertia ixx="0.00001" ixy="0" ixz="0" iyy="0.00001" iyz="0" izz="0.00001"/>
		</inertial>
		<collision>
			<origin rpy="0.00000 -0.00000 0.00000" xyz="0.00000 0.00000 0.00000"/>
			<geometry>
				<sphere radius="0.02150"/>
			</geometry>
		</collision>
		<visual>
			<origin rpy="0.00000 -0.00000 0.00000" xyz="0.00000 0.00000 0.00000"/>
			<geometry>
				<sphere radius="0.02150"/>
			</geometry>
		</visual>
	</link>
	<link name="l31_right">
		<inertial>
			<origin rpy="0.00000 -0.00000 0.00000" xyz="0.00000 0.00000 0.00000"/>
			<mass value="0.00043"/>
			<inertia ixx="0.00000" ixy="0" ixz="0" iyy="0.00000" iyz="0" izz="0.00000"/>
		</inertial>
		<collision>
			<origin rpy="0.00000 -0.00000 0.00000" xyz="0.00000 0.00000 0.00000"/>
			<geometry>
				<box size="0.03600 0.00400 0.00300"/>
			</geometry>
		</collision>
		<visual>
			<origin rpy="0.00000 -0.00000 0.00000" xyz="0.00000 0.00000 0.00000"/>
			<geometry>
				<box size="0.03600 0.00400 0.00300"/>
			</geometry>
		</visual>
	</link>
	<link name="l32_right">
		<inertial>
			<origin rpy="0.00000 -0.00000 0.00000" xyz="0.00000 0.00000 0.00000"/>
			<mass value="0.00043"/>
			<inertia ixx="0.00000" ixy="0" ixz="0" iyy="0.00000" iyz="0" izz="0.00000"/>
		</inertial>
		<collision>
			<origin rpy="0.00000 -0.00000 0.00000" xyz="0.00000 0.00000 0.00000"/>
			<geometry>
				<box size="0.03600 0.00400 0.00300"/>
			</geometry>
		</collision>
		<visual>
			<origin rpy="0.00000 -0.00000 0.00000" xyz="0.00000 0.00000 0.00000"/>
			<geometry>
				<box size="0.03600 0.00400 0.00300"/>
			</geometry>
		</visual>
	</link>
	<joint name="r1_front" type="revolute">
		<parent link="base_link"/>
		<child link="link0_2"/>
		<dynamics damping="1.0" friction="0.0001"/>
		<origin rpy="0.00000 -0.00000 1.57080" xyz="0.00000 0.04800 0.04500"/>
		<axis xyz="0.00000 1.00000 0.00000"/>
	</joint>
	<joint name="jointfix_5_2" type="fixed">
		<parent link="link0_2"/>
		<child link="l1_front"/>
		<dynamics damping="1.0" friction="0.0001"/>
		<origin rpy="0.00000 -0.00000 0.00000" xyz="0.02000 0.00000 0.00500"/>
		<axis xyz="0.00000 0.00000 0.00000"/>
	</joint>
	<joint name="jointfix_4_1" type="fixed">
		<parent link="l1_front"/>
		<child link="l11_front"/>
		<dynamics damping="1.0" friction="0.0001"/>
		<origin rpy="0.00000 -0.00000 0.00000" xyz="0.02500 0.00000 0.05825"/>
		<axis xyz="0.00000 0.00000 0.00000"/>
	</joint>
	<joint name="r2_front" type="revolute">
		<parent link="l11_front"/>
		<child link="link0_5"/>
		<dynamics damping="1.0" friction="0.0001"/>
		<origin rpy="0.00000 -0.00000 0.00000" xyz="-0.01000 0.00000 0.05825"/>
		<axis xyz="1.00000 0.00000 0.00000"/>
	</joint>
	<joint name="jointfix_3_5" type="fixed">
		<parent link="link0_5"/>
		<child link="l2_front"/>
		<dynamics damping="1.0" friction="0.0001"/>
		<origin rpy="0.00000 -0.00000 0.00000" xyz="0.00000 0.00000 0.00000"/>
		<axis xyz="0.00000 0.00000 0.00000"/>
	</joint>
	<joint name="r3_front" type="revolute">
		<parent link="l2_front"/>
		<child link="link0_7"/>
		<dynamics damping="1.0" friction="0.0001"/>
		<origin rpy="0.00000 -0.00000 0.00000" xyz="-0.03500 0.00000 0.00000"/>
		<axis xyz="0.00000 0.00000 1.00000"/>
	</joint>
	<joint name="jointfix_0_7" type="fixed">
		<parent link="link0_7"/>
		<child link="l3_front"/>
		<dynamics damping="1.0" friction="0.0001"/>
		<origin rpy="0.00000 -0.00000 0.00000" xyz="0.00000 0.00000 0.00000"/>
		<axis xyz="0.00000 0.00000 0.00000"/>
	</joint>
	<joint name="jointfix_1_4" type="fixed">
		<parent link="l2_front"/>
		<child link="l31_front"/>
		<dynamics damping="1.0" friction="0.0001"/>
		<origin rpy="0.00000 -0.00000 0.00000" xyz="-0.02300 0.00000 -0.02350"/>
		<axis xyz="0.00000 0.00000 0.00000"/>
	</joint>
	<joint name="jointfix_2_4" type="fixed">
		<parent link="l2_front"/>
		<child link="l32_front"/>
		<dynamics damping="1.0" friction="0.0001"/>
		<origin rpy="0.00000 -0.00000 0.00000" xyz="-0.02300 0.00000 0.02350"/>
		<axis xyz="0.00000 0.00000 0.00000"/>
	</joint>
	<joint name="r1_left" type="revolute">
		<parent link="base_link"/>
		<child link="link0_11"/>
		<dynamics damping="1.0" friction="0.0001"/>
		<origin rpy="0.00000 -0.00000 -2.61768" xyz="-0.04157 -0.02399 0.04500"/>
		<axis xyz="0.00000 1.00000 0.00000"/>
	</joint>
	<joint name="jointfix_11_11" type="fixed">
		<parent link="link0_11"/>
		<child link="l1_left"/>
		<dynamics damping="1.0" friction="0.0001"/>
		<origin rpy="0.00000 -0.00000 0.00000" xyz="0.02000 0.00000 0.00500"/>
		<axis xyz="0.00000 0.00000 0.00000"/>
	</joint>
	<joint name="jointfix_10_10" type="fixed">
		<parent link="l1_left"/>
		<child link="l11_left"/>
		<dynamics damping="1.0" friction="0.0001"/>
		<origin rpy="0.00000 -0.00000 0.00000" xyz="0.02500 0.00000 0.05825"/>
		<axis xyz="0.00000 0.00000 0.00000"/>
	</joint>
	<joint name="r2_left" type="revolute">
		<parent link="l11_left"/>
		<child link="link0_14"/>
		<dynamics damping="1.0" friction="0.0001"/>
		<origin rpy="0.00000 -0.00000 0.00000" xyz="-0.01000 0.00000 0.05825"/>
		<axis xyz="1.00000 0.00000 0.00000"/>
	</joint>
	<joint name="jointfix_9_14" type="fixed">
		<parent link="link0_14"/>
		<child link="l2_left"/>
		<dynamics damping="1.0" friction="0.0001"/>
		<origin rpy="0.00000 -0.00000 0.00000" xyz="0.00000 0.00000 0.00000"/>
		<axis xyz="0.00000 0.00000 0.00000"/>
	</joint>
	<joint name="r3_left" type="revolute">
		<parent link="l2_left"/>
		<child link="link0_16"/>
		<dynamics damping="1.0" friction="0.0001"/>
		<origin rpy="0.00000 -0.00000 0.00000" xyz="-0.03500 0.00000 0.00000"/>
		<axis xyz="0.00000 0.00000 1.00000"/>
	</joint>
	<joint name="jointfix_6_16" type="fixed">
		<parent link="link0_16"/>
		<child link="l3_left"/>
		<dynamics damping="1.0" friction="0.0001"/>
		<origin rpy="0.00000 -0.00000 0.00000" xyz="0.00000 0.00000 0.00000"/>
		<axis xyz="0.00000 0.00000 0.00000"/>
	</joint>
	<joint name="jointfix_7_13" type="fixed">
		<parent link="l2_left"/>
		<child link="l31_left"/>
		<dynamics damping="1.0" friction="0.0001"/>
		<origin rpy="0.00000 -0.00000 0.00000" xyz="-0.02300 0.00000 -0.02350"/>
		<axis xyz="0.00000 0.00000 0.00000"/>
	</joint>
	<joint name="jointfix_8_13" type="fixed">
		<parent link="l2_left"/>
		<child link="l32_left"/>
		<dynamics damping="1.0" friction="0.0001"/>
		<origin rpy="0.00000 -0.00000 0.00000" xyz="-0.02300 0.00000 0.02350"/>
		<axis xyz="0.00000 0.00000 0.00000"/>
	</joint>
	<joint name="r1_right" type="revolute">
		<parent link="base_link"/>
		<child link="link0_20"/>
		<dynamics damping="1.0" friction="0.0001"/>
		<origin rpy="0.00000 0.00000 -0.52391" xyz="0.04157 -0.02399 0.04500"/>
		<axis xyz="0.00000 1.00000 0.00000"/>
	</joint>
	<joint name="jointfix_17_20" type="fixed">
		<parent link="link0_20"/>
		<child link="l1_right"/>
		<dynamics damping="1.0" friction="0.0001"/>
		<origin rpy="0.00000 -0.00000 0.00000" xyz="0.02000 0.00000 0.00500"/>
		<axis xyz="0.00000 0.00000 0.00000"/>
	</joint>
	<joint name="jointfix_16_19" type="fixed">
		<parent link="l1_right"/>
		<child link="l11_right"/>
		<dynamics damping="1.0" friction="0.0001"/>
		<origin rpy="0.00000 -0.00000 0.00000" xyz="0.02500 0.00000 0.05825"/>
		<axis xyz="0.00000 0.00000 0.00000"/>
	</joint>
	<joint name="r2_right" type="revolute">
		<parent link="l11_right"/>
		<child link="link0_23"/>
		<dynamics damping="1.0" friction="0.0001"/>
		<origin rpy="0.00000 -0.00000 0.00000" xyz="-0.01000 0.00000 0.05825"/>
		<axis xyz="1.00000 0.00000 0.00000"/>
	</joint>
	<joint name="jointfix_15_23" type="fixed">
		<parent link="link0_23"/>
		<child link="l2_right"/>
		<dynamics damping="1.0" friction="0.0001"/>
		<origin rpy="0.00000 -0.00000 0.00000" xyz="0.00000 0.00000 0.00000"/>
		<axis xyz="0.00000 0.00000 0.00000"/>
	</joint>
	<joint name="r3_right" type="revolute">
		<parent link="l2_right"/>
		<child link="link0_25"/>
		<dynamics damping="1.0" friction="0.0001"/>
		<origin rpy="0.00000 -0.00000 0.00000" xyz="-0.03500 0.00000 0.00000"/>
		<axis xyz="0.00000 0.00000 1.00000"/>
	</joint>
	<joint name="jointfix_12_25" type="fixed">
		<parent link="link0_25"/>
		<child link="l3_right"/>
		<dynamics damping="1.0" friction="0.0001"/>
		<origin rpy="0.00000 -0.00000 0.00000" xyz="0.00000 0.00000 0.00000"/>
		<axis xyz="0.00000 0.00000 0.00000"/>
	</joint>
	<joint name="jointfix_13_22" type="fixed">
		<parent link="l2_right"/>
		<child link="l31_right"/>
		<dynamics damping="1.0" friction="0.0001"/>
		<origin rpy="0.00000 -0.00000 0.00000" xyz="-0.02300 0.00000 -0.02350"/>
		<axis xyz="0.00000 0.00000 0.00000"/>
	</joint>
	<joint name="jointfix_14_22" type="fixed">
		<parent link="l2_right"/>
		<child link="l32_right"/>
		<dynamics damping="1.0" friction="0.0001"/>
		<origin rpy="0.00000 -0.00000 0.00000" xyz="-0.02300 0.00000 0.02350"/>
		<axis xyz="0.00000 0.00000 0.00000"/>
	</joint>
</robot>
